Workbook

Sheet PlantInfo
A1: Source | B1: Commissioning Group | C1: Name of Power Plant | D1: State | E1: District | F1: Commissioning Date | G1: Capacity (MW) | H1: Implementing Agency
A2: Coal | B2: pipeline | C2: Ennore SEZ Expansion SCTPP | D2: Tamil Nadu | E2: Tiruvallur | F2: 2027-06-01 | G2: 660 | H2: Tamil Nadu Generation & Distribution Corp. Ltd. (TANGEDCO)
A3: Coal | B3: pipeline | C3: Ennore SEZ Expansion SCTPP | D3: Tamil Nadu | E3: Tiruvallur | F3: 2027-08-01 | G3: 660 | H3: Tamil Nadu Generation & Distribution Corp. Ltd. (TANGEDCO)
A4: Coal | B4: retired | C4: Ennore TPS | D4: Tamil Nadu | E4: Thiruvallur | F4: 1970-03-01 | G4: 60 | H4: Tamil Nadu Generation & Distribution Corp. Ltd. (TANGEDCO)
A5: Coal | B5: retired | C5: Ennore TPS | D5: Tamil Nadu | E5: Thiruvallur | F5: 1971-02-01 | G5: 60 | H5: Tamil Nadu Generation & Distribution Corp. Ltd. (TANGEDCO)
A6: Coal | B6: retired | C6: Ennore TPS | D6: Tamil Nadu | E6: Thiruvallur | F6: 1972-05-01 | G6: 110 | H6: Tamil Nadu Generation & Distribution Corp. Ltd. (TANGEDCO)
A7: Coal | B7: retired | C7: Ennore TPS | D7: Tamil Nadu | E7: Thiruvallur | F7: 1973-05-01 | G7: 110 | H7: Tamil Nadu Generation & Distribution Corp. Ltd. (TANGEDCO)
A8: Coal | B8: retired | C8: Ennore TPS | D8: Tamil Nadu | E8: Thiruvallur | F8: 1975-12-01 | G8: 110 | H8: Tamil Nadu Generation & Distribution Corp. Ltd. (TANGEDCO)
A9: Coal | B9: operational | C9: ITPCL or Cuddalore TPP | D9: Tamil Nadu | E9: Cuddalore | F9: 2015-09-01 | G9: 600 | H9: IL&FS Tamil Nadu Power Co. Ltd.
A10: Coal | B10: operational | C10: ITPCL or Cuddalore TPP | D10: Tamil Nadu | E10: Cuddalore | F10: 2016-04-01 | G10: 600 | H10: IL&FS Tamil Nadu Power Co. Ltd.
A11: Coal | B11: operational | C11: Mettur TPS | D11: Tamil Nadu | E11: Salem | F11: 1987-01-07 | G11: 210 | H11: Tamil Nadu Generation & Distribution Corp. Ltd. (TANGEDCO)
A12: Coal | B12: operational | C12: Mettur TPS | D12: Tamil Nadu | E12: Salem | F12: 1987-01-12 | G12: 210 | H12: Tamil Nadu Generation & Distribution Corp. Ltd. (TANGEDCO)
A13: Coal | B13: operational | C13: Mettur TPS | D13: Tamil Nadu | E13: Salem | F13: 1989-03-22 | G13: 210 | H13: Tamil Nadu Generation & Distribution Corp. Ltd. (TANGEDCO)
... A142: Hydro | B142: operational | C142: Suruliyar Hydroelectric Power Project | D142: Tamil Nadu | E142: Theni | F142: 1978-08-27 | G142: 35 | H142: Tamil Nadu Generation & Distribution Co. Limited (TANGEDCO)
A143: Wind | B143: pipeline | C143: 151 MW SJVN Wind Palayam Green Shoe Tamil Nadu Karur | D143: Tamil Nadu | E143: Karur | G143: 151.2
A144: Wind | B144: pipeline | C144: 151.2 MW Wind SJVN FDRE Basis LOA Tamil Nadu Karur | D144: Tamil Nadu | E144: Karur | G144: 151.2
A145: Wind | B145: pipeline | C145: 82.5 MW NTPC FDRE Wind Tamil Nadu Karur | D145: Tamil Nadu | E145: Karur | G145: 82.5
A146: Wind | B146: pipeline | C146: 93.6 MW Karur - SJVN FDRE Green Shoe Tamil Nadu Karur | D146: Tamil Nadu | E146: Karur | G146: 93.6
A147: Wind | B147: pipeline | C147: Amplus Sun Beat Private Limited Tamil Nadu Karur | D147: Tamil Nadu | E147: Karur | G147: 80
A148: Wind | B148: pipeline | C148: Amplus Theta Energy Private Limited Tamil Nadu Karur | D148: Tamil Nadu | E148: Karur | G148: 65
A149: Wind | B149: pipeline | C149: Jindal Renewables - Wind Project - C&I Tamil Nadu Karur | D149: Tamil Nadu | E149: Karur | G149: 300
A150: Wind | B150: pipeline | C150: Jindal Renewables - Wind Project - C&I Tamil Nadu Karur | D150: Tamil Nadu | E150: Karur | G150: 50
A151: Wind | B151: operational | C151: Tamil Nadu-Ariyalur | D151: Tamil Nadu | E151: Ariyalur | G151: 22
A152: Wind | B152: operational | C152: Tamil Nadu-Chennai | D152: Tamil Nadu | E152: Chennai | G152: 3.125
A153: Wind | B153: operational | C153: Tamil Nadu-Coimbatore | D153: Tamil Nadu | E153: Coimbatore | G153: 2175.4
A154: Wind | B154: operational | C154: Tamil Nadu-Dharmapuri | D154: Tamil Nadu | E154: Dharmapuri | G154: 196
... A172: Wind | B172: operational | C172: Tamil Nadu-Viluppuram | D172: Tamil Nadu | E172: Viluppuram | G172: 1.7
A173: Solar | B173: pipeline | C173: INGEL Tamil Nadu 200.0 | D173: Tamil Nadu | E173: Thoothukudi | F173: 2027-12-31 | G173: 200 | H173: INGEL
A174: Solar | B174: operational | C174: Tamil Nadu Chennai 16 | D174: Tamil Nadu | E174: Chennai | G174: 16
A175: Solar | B175: operational | C175: Tamil Nadu Coimbatore 11.26 | D175: Tamil Nadu | E175: Coimbatore | G175: 11.26
A176: Solar | B176: operational | C176: Tamil Nadu Cuddalore 140 | D176: Tamil Nadu | E176: Cuddalore | G176: 140
A177: Solar | B177: operational | C177: Tamil Nadu Dindigul 109.46 | D177: Tamil Nadu | E177: Dindigul | G177: 109.46
A178: Solar | B178: operational | C178: Tamil Nadu Erode 7 | D178: Tamil Nadu | E178: Erode | G178: 7
A179: Solar | B179: operational | C179: Tamil Nadu Kanniyakumari 1 | D179: Tamil Nadu | E179: Kanniyakumari | G179: 1
A180: Solar | B180: operational | C180: Tamil Nadu Karur 156.49 | D180: Tamil Nadu | E180: Karur | G180: 156.49
A181: Solar | B181: operational | C181: Tamil Nadu Krishnagiri 0.75 | D181: Tamil Nadu | E181: Krishnagiri | G181: 0.75
A182: Solar | B182: operational | C182: Tamil Nadu Madurai 1 | D182: Tamil Nadu | E182: Madurai | G182: 1
A183: Solar | B183: operational | C183: Tamil Nadu N.A. 251 | D183: Tamil Nadu | E183: N.A. | G183: 251
A184: Solar | B184: operational | C184: Tamil Nadu N.A. Off -grid 75.91 | D184: Tamil Nadu | E184: N.A. | G184: 75.91
A185: Solar | B185: operational | C185: Tamil Nadu N.A. Others (Districts not specified) 9143.18 | D185: Tamil Nadu | E185: N.A. | G185: 9143.18
...

Sheet District Allocation
A1: Source Record ID | B1: Allocation ID | C1: Base Excel Row | D1: Source | E1: Commissioning Group | F1: Name of Power Plant | G1: State | H1: Source District | I1: Allocated District | J1: Commissioning Date | K1: Source Capacity (MW) | L1: Allocation Share | M1: Allocated Capacity (MW) | N1: Verified Allocated Capacity (MW) | O1: Implementing Agency | P1: Allocation Component | Q1: Allocation Method | R1: Confidence | S1: Source URL | T1: Notes
A2: SEP26-0002 | B2: base_row_0002 | C2: 2 | D2: Coal | E2: pipeline | F2: Ennore SEZ Expansion SCTPP | G2: Tamil Nadu | H2: Tiruvallur | I2: Tiruvallur | J2: 2027-06-01 | K2: 660 | L2: 1 | M2: =K2*L2 | N2: 660 | O2: Tamil Nadu Generation & Distribution Corp. Ltd. (TANGEDCO) | P2: Direct | Q2: District carried from Sep26 base workbook | R2: Existing | T2: Sep26 is authoritative for the source record.
A3: SEP26-0003 | B3: base_row_0003 | C3: 3 | D3: Coal | E3: pipeline | F3: Ennore SEZ Expansion SCTPP | G3: Tamil Nadu | H3: Tiruvallur | I3: Tiruvallur | J3: 2027-08-01 | K3: 660 | L3: 1 | M3: =K3*L3 | N3: 660 | O3: Tamil Nadu Generation & Distribution Corp. Ltd. (TANGEDCO) | P3: Direct | Q3: District carried from Sep26 base workbook | R3: Existing | T3: Sep26 is authoritative for the source record.
A4: SEP26-0004 | B4: base_row_0004 | C4: 4 | D4: Coal | E4: retired | F4: Ennore TPS | G4: Tamil Nadu | H4: Thiruvallur | I4: Tiruvallur | J4: 1970-03-01 | K4: 60 | L4: 1 | M4: =K4*L4 | N4: 60 | O4: Tamil Nadu Generation & Distribution Corp. Ltd. (TANGEDCO) | P4: Direct | Q4: District carried from Sep26 base workbook | R4: Existing | T4: Sep26 is authoritative for the source record.
A5: SEP26-0005 | B5: base_row_0005 | C5: 5 | D5: Coal | E5: retired | F5: Ennore TPS | G5: Tamil Nadu | H5: Thiruvallur | I5: Tiruvallur | J5: 1971-02-01 | K5: 60 | L5: 1 | M5: =K5*L5 | N5: 60 | O5: Tamil Nadu Generation & Distribution Corp. Ltd. (TANGEDCO) | P5: Direct | Q5: District carried from Sep26 base workbook | R5: Existing | T5: Sep26 is authoritative for the source record.
A6: SEP26-0006 | B6: base_row_0006 | C6: 6 | D6: Coal | E6: retired | F6: Ennore TPS | G6: Tamil Nadu | H6: Thiruvallur | I6: Tiruvallur | J6: 1972-05-01 | K6: 110 | L6: 1 | M6: =K6*L6 | N6: 110 | O6: Tamil Nadu Generation & Distribution Corp. Ltd. (TANGEDCO) | P6: Direct | Q6: District carried from Sep26 base workbook | R6: Existing | T6: Sep26 is authoritative for the source record.
A7: SEP26-0007 | B7: base_row_0007 | C7: 7 | D7: Coal | E7: retired | F7: Ennore TPS | G7: Tamil Nadu | H7: Thiruvallur | I7: Tiruvallur | J7: 1973-05-01 | K7: 110 | L7: 1 | M7: =K7*L7 | N7: 110 | O7: Tamil Nadu Generation & Distribution Corp. Ltd. (TANGEDCO) | P7: Direct | Q7: District carried from Sep26 base workbook | R7: Existing | T7: Sep26 is authoritative for the source record.
A8: SEP26-0008 | B8: base_row_0008 | C8: 8 | D8: Coal | E8: retired | F8: Ennore TPS | G8: Tamil Nadu | H8: Thiruvallur | I8: Tiruvallur | J8: 1975-12-01 | K8: 110 | L8: 1 | M8: =K8*L8 | N8: 110 | O8: Tamil Nadu Generation & Distribution Corp. Ltd. (TANGEDCO) | P8: Direct | Q8: District carried from Sep26 base workbook | R8: Existing | T8: Sep26 is authoritative for the source record.
A9: SEP26-0009 | B9: base_row_0009 | C9: 9 | D9: Coal | E9: operational | F9: ITPCL or Cuddalore TPP | G9: Tamil Nadu | H9: Cuddalore | I9: Cuddalore | J9: 2015-09-01 | K9: 600 | L9: 1 | M9: =K9*L9 | N9: 600 | O9: IL&FS Tamil Nadu Power Co. Ltd. | P9: Direct | Q9: District carried from Sep26 base workbook | R9: Existing | T9: Sep26 is authoritative for the source record.
A10: SEP26-0010 | B10: base_row_0010 | C10: 10 | D10: Coal | E10: operational | F10: ITPCL or Cuddalore TPP | G10: Tamil Nadu | H10: Cuddalore | I10: Cuddalore | J10: 2016-04-01 | K10: 600 | L10: 1 | M10: =K10*L10 | N10: 600 | O10: IL&FS Tamil Nadu Power Co. Ltd. | P10: Direct | Q10: District carried from Sep26 base workbook | R10: Existing | T10: Sep26 is authoritative for the source record.
A11: SEP26-0011 | B11: base_row_0011 | C11: 11 | D11: Coal | E11: operational | F11: Mettur TPS | G11: Tamil Nadu | H11: Salem | I11: Salem | J11: 1987-01-07 | K11: 210 | L11: 1 | M11: =K11*L11 | N11: 210 | O11: Tamil Nadu Generation & Distribution Corp. Ltd. (TANGEDCO) | P11: Direct | Q11: District carried from Sep26 base workbook | R11: Existing | T11: Sep26 is authoritative for the source record.
A12: SEP26-0012 | B12: base_row_0012 | C12: 12 | D12: Coal | E12: operational | F12: Mettur TPS | G12: Tamil Nadu | H12: Salem | I12: Salem | J12: 1987-01-12 | K12: 210 | L12: 1 | M12: =K12*L12 | N12: 210 | O12: Tamil Nadu Generation & Distribution Corp. Ltd. (TANGEDCO) | P12: Direct | Q12: District carried from Sep26 base workbook | R12: Existing | T12: Sep26 is authoritative for the source record.
A13: SEP26-0013 | B13: base_row_0013 | C13: 13 | D13: Coal | E13: operational | F13: Mettur TPS | G13: Tamil Nadu | H13: Salem | I13: Salem | J13: 1989-03-22 | K13: 210 | L13: 1 | M13: =K13*L13 | N13: 210 | O13: Tamil Nadu Generation & Distribution Corp. Ltd. (TANGEDCO) | P13: Direct | Q13: District carried from Sep26 base workbook | R13: Existing | T13: Sep26 is authoritative for the source record.
... A142: SEP26-0142 | B142: base_row_0142 | C142: 142 | D142: Hydro | E142: operational | F142: Suruliyar Hydroelectric Power Project | G142: Tamil Nadu | H142: Theni | I142: Theni | J142: 1978-08-27 | K142: 35 | L142: 1 | M142: =K142*L142 | N142: 35 | O142: Tamil Nadu Generation & Distribution Co. Limited (TANGEDCO) | P142: Direct | Q142: District carried from Sep26 base workbook | R142: Existing | T142: Sep26 is authoritative for the source record.
A143: SEP26-0143 | B143: base_row_0143 | C143: 143 | D143: Wind | E143: pipeline | F143: 151 MW SJVN Wind Palayam Green Shoe Tamil Nadu Karur | G143: Tamil Nadu | H143: Karur | I143: Karur | K143: 151.2 | L143: 1 | M143: =K143*L143 | N143: 151.2 | P143: Direct | Q143: District carried from Sep26 base workbook | R143: Existing | T143: Sep26 is authoritative for the source record.
A144: SEP26-0144 | B144: base_row_0144 | C144: 144 | D144: Wind | E144: pipeline | F144: 151.2 MW Wind SJVN FDRE Basis LOA Tamil Nadu Karur | G144: Tamil Nadu | H144: Karur | I144: Karur | K144: 151.2 | L144: 1 | M144: =K144*L144 | N144: 151.2 | P144: Direct | Q144: District carried from Sep26 base workbook | R144: Existing | T144: Sep26 is authoritative for the source record.
A145: SEP26-0145 | B145: base_row_0145 | C145: 145 | D145: Wind | E145: pipeline | F145: 82.5 MW NTPC FDRE Wind Tamil Nadu Karur | G145: Tamil Nadu | H145: Karur | I145: Karur | K145: 82.5 | L145: 1 | M145: =K145*L145 | N145: 82.5 | P145: Direct | Q145: District carried from Sep26 base workbook | R145: Existing | T145: Sep26 is authoritative for the source record.
A146: SEP26-0146 | B146: base_row_0146 | C146: 146 | D146: Wind | E146: pipeline | F146: 93.6 MW Karur - SJVN FDRE Green Shoe Tamil Nadu Karur | G146: Tamil Nadu | H146: Karur | I146: Karur | K146: 93.6 | L146: 1 | M146: =K146*L146 | N146: 93.6 | P146: Direct | Q146: District carried from Sep26 base workbook | R146: Existing | T146: Sep26 is authoritative for the source record.
A147: SEP26-0147 | B147: base_row_0147 | C147: 147 | D147: Wind | E147: pipeline | F147: Amplus Sun Beat Private Limited Tamil Nadu Karur | G147: Tamil Nadu | H147: Karur | I147: Karur | K147: 80 | L147: 1 | M147: =K147*L147 | N147: 80 | P147: Direct | Q147: District carried from Sep26 base workbook | R147: Existing | T147: Sep26 is authoritative for the source record.
A148: SEP26-0148 | B148: base_row_0148 | C148: 148 | D148: Wind | E148: pipeline | F148: Amplus Theta Energy Private Limited Tamil Nadu Karur | G148: Tamil Nadu | H148: Karur | I148: Karur | K148: 65 | L148: 1 | M148: =K148*L148 | N148: 65 | P148: Direct | Q148: District carried from Sep26 base workbook | R148: Existing | T148: Sep26 is authoritative for the source record.
A149: SEP26-0149 | B149: base_row_0149 | C149: 149 | D149: Wind | E149: pipeline | F149: Jindal Renewables - Wind Project - C&I Tamil Nadu Karur | G149: Tamil Nadu | H149: Karur | I149: Karur | K149: 300 | L149: 1 | M149: =K149*L149 | N149: 300 | P149: Direct | Q149: District carried from Sep26 base workbook | R149: Existing | T149: Sep26 is authoritative for the source record.
A150: SEP26-0150 | B150: base_row_0150 | C150: 150 | D150: Wind | E150: pipeline | F150: Jindal Renewables - Wind Project - C&I Tamil Nadu Karur | G150: Tamil Nadu | H150: Karur | I150: Karur | K150: 50 | L150: 1 | M150: =K150*L150 | N150: 50 | P150: Direct | Q150: District carried from Sep26 base workbook | R150: Existing | T150: Sep26 is authoritative for the source record.
A151: SEP26-0151 | B151: base_row_0151 | C151: 151 | D151: Wind | E151: operational | F151: Tamil Nadu-Ariyalur | G151: Tamil Nadu | H151: Ariyalur | I151: Ariyalur | K151: 22 | L151: 1 | M151: =K151*L151 | N151: 22 | P151: Direct | Q151: District carried from Sep26 base workbook | R151: Existing | T151: Sep26 is authoritative for the source record.
A152: SEP26-0152 | B152: base_row_0152 | C152: 152 | D152: Wind | E152: operational | F152: Tamil Nadu-Chennai | G152: Tamil Nadu | H152: Chennai | I152: Chennai | K152: 3.125 | L152: 1 | M152: =K152*L152 | N152: 3.125 | P152: Direct | Q152: District carried from Sep26 base workbook | R152: Existing | T152: Sep26 is authoritative for the source record.
A153: SEP26-0153 | B153: base_row_0153 | C153: 153 | D153: Wind | E153: operational | F153: Tamil Nadu-Coimbatore | G153: Tamil Nadu | H153: Coimbatore | I153: Coimbatore | K153: 2175.4 | L153: 1 | M153: =K153*L153 | N153: 2175.4 | P153: Direct | Q153: District carried from Sep26 base workbook | R153: Existing | T153: Sep26 is authoritative for the source record.
A154: SEP26-0154 | B154: base_row_0154 | C154: 154 | D154: Wind | E154: operational | F154: Tamil Nadu-Dharmapuri | G154: Tamil Nadu | H154: Dharmapuri | I154: Dharmapuri | K154: 196 | L154: 1 | M154: =K154*L154 | N154: 196 | P154: Direct | Q154: District carried from Sep26 base workbook | R154: Existing | T154: Sep26 is authoritative for the source record.
... A159: SEP26-0159 | B159: base_row_0159 | C159: 159 | D159: Wind | E159: operational | F159: Tamil Nadu-Karur | G159: Tamil Nadu | H159: Karur | I159: Karur | K159: 549.595 | L159: 1 | M159: =K159*L159 | N159: 549.595 | P159: Direct | Q159: District carried from Sep26 base workbook | R159: Existing | T159: Sep26 is authoritative for the source record.
A160: SEP26-0160 | B160: wind_unspecified | C160: 160 | D160: Wind | E160: operational | F160: Tamil Nadu-N.A. | G160: Tamil Nadu | H160: N.A. | I160: Dindigul | K160: 256.375 | L160: 0.0060256568 | M160: =K160*L160 | N160: 1.5448278 | P160: Wind Residual | Q160: Residual-gap allocation using current district assignment of supplied OSM turbines and Sep26 known district capacities | R160: Medium | S160: https://cdn.jsdelivr.net/gh/udit-001/india-maps-data@2884453/geojson/states/tamil-nadu.geojson | T160: Recalculated for Sep26. Tenkasi is separate; Chengalpattu, Kallakurichi, Ranipet, Tirupathur, and Mayiladuthurai are recombined to the established allocation geography.
A161: SEP26-0160 | B161: wind_unspecified | C161: 160 | D161: Wind | E161: operational | F161: Tamil Nadu-N.A. | G161: Tamil Nadu | H161: N.A. | I161: Tenkasi | K161: 256.375 | L161: 0.40357922 | M161: =K161*L161 | N161: 103.46762 | P161: Wind Residual | Q161: Residual-gap allocation using current district assignment of supplied OSM turbines and Sep26 known district capacities | R161: Medium | S161: https://cdn.jsdelivr.net/gh/udit-001/india-maps-data@2884453/geojson/states/tamil-nadu.geojson | T161: Recalculated for Sep26. Tenkasi is separate; Chengalpattu, Kallakurichi, Ranipet, Tirupathur, and Mayiladuthurai are recombined to the established allocation geography.
A162: SEP26-0160 | B162: wind_unspecified | C162: 160 | D162: Wind | E162: operational | F162: Tamil Nadu-N.A. | G162: Tamil Nadu | H162: N.A. | I162: Tiruppur | K162: 256.375 | L162: 0.59034698 | M162: =K162*L162 | N162: 151.35021 | P162: Wind Residual | Q162: Residual-gap allocation using current district assignment of supplied OSM turbines and Sep26 known district capacities | R162: Medium | S162: https://cdn.jsdelivr.net/gh/udit-001/india-maps-data@2884453/geojson/states/tamil-nadu.geojson | T162: Recalculated for Sep26. Tenkasi is separate; Chengalpattu, Kallakurichi, Ranipet, Tirupathur, and Mayiladuthurai are recombined to the established allocation geography.
A163: SEP26-0160 | B163: wind_unspecified | C163: 160 | D163: Wind | E163: operational | F163: Tamil Nadu-N.A. | G163: Tamil Nadu | H163: N.A. | I163: Viluppuram | K163: 256.375 | L163: 4.8141459e-05 | M163: =K163*L163 | N163: 0.012342267 | P163: Wind Residual | Q163: Residual-gap allocation using current district assignment of supplied OSM turbines and Sep26 known district capacities | R163: Medium | S163: https://cdn.jsdelivr.net/gh/udit-001/india-maps-data@2884453/geojson/states/tamil-nadu.geojson | T163: Recalculated for Sep26. Tenkasi is separate; Chengalpattu, Kallakurichi, Ranipet, Tirupathur, and Mayiladuthurai are recombined to the established allocation geography.
A164: SEP26-0161 | B164: base_row_0161 | C164: 161 | D164: Wind | E164: operational | F164: Tamil Nadu-Ramanathapuram | G164: Tamil Nadu | H164: Ramanathapuram | I164: Ramanathapuram | K164: 34.03 | L164: 1 | M164: =K164*L164 | N164: 34.03 | P164: Direct | Q164: District carried from Sep26 base workbook | R164: Existing | T164: Sep26 is authoritative for the source record.
A165: SEP26-0162 | B165: base_row_0162 | C165: 162 | D165: Wind | E165: operational | F165: Tamil Nadu-Salem | G165: Tamil Nadu | H165: Salem | I165: Salem | K165: 3.4 | L165: 1 | M165: =K165*L165 | N165: 3.4 | P165: Direct | Q165: District carried from Sep26 base workbook | R165: Existing | T165: Sep26 is authoritative for the source record.
A166: SEP26-0163 | B166: base_row_0163 | C166: 163 | D166: Wind | E166: operational | F166: Tamil Nadu-Tenkasi | G166: Tamil Nadu | H166: Tenkasi | I166: Tenkasi | K166: 22.88 | L166: 1 | M166: =K166*L166 | N166: 22.88 | P166: Direct | Q166: District carried from Sep26 base workbook | R166: Existing | T166: Sep26 is authoritative for the source record.
A167: SEP26-0164 | B167: base_row_0164 | C167: 164 | D167: Wind | E167: operational | F167: Tamil Nadu-Thanjavur | G167: Tamil Nadu | H167: Thanjavur | I167: Thanjavur | K167: 8.8 | L167: 1 | M167: =K167*L167 | N167: 8.8 | P167: Direct | Q167: District carried from Sep26 base workbook | R167: Existing | T167: Sep26 is authoritative for the source record.
A168: SEP26-0165 | B168: base_row_0165 | C168: 165 | D168: Wind | E168: operational | F168: Tamil Nadu-Theni | G168: Tamil Nadu | H168: Theni | I168: Theni | K168: 574.6 | L168: 1 | M168: =K168*L168 | N168: 574.6 | P168: Direct | Q168: District carried from Sep26 base workbook | R168: Existing | T168: Sep26 is authoritative for the source record.
A169: SEP26-0166 | B169: base_row_0166 | C169: 166 | D169: Wind | E169: operational | F169: Tamil Nadu-Thiruvallur | G169: Tamil Nadu | H169: Thiruvallur | I169: Tiruvallur | K169: 7.2 | L169: 1 | M169: =K169*L169 | N169: 7.2 | P169: Direct | Q169: District carried from Sep26 base workbook | R169: Existing | T169: Sep26 is authoritative for the source record.
A170: SEP26-0167 | B170: base_row_0167 | C170: 167 | D170: Wind | E170: operational | F170: Tamil Nadu-Thoothukkudi | G170: Tamil Nadu | H170: Thoothukkudi | I170: Thoothukudi | K170: 2662.925 | L170: 1 | M170: =K170*L170 | N170: 2662.925 | P170: Direct | Q170: District carried from Sep26 base workbook | R170: Existing | T170: Sep26 is authoritative for the source record.
A171: SEP26-0168 | B171: base_row_0168 | C171: 168 | D171: Wind | E171: operational | F171: Tamil Nadu-Tiruchirappalli | G171: Tamil Nadu | H171: Tiruchirappalli | I171: Tiruchirappalli | K171: 16.9 | L171: 1 | M171: =K171*L171 | N171: 16.9 | P171: Direct | Q171: District carried from Sep26 base workbook | R171: Existing | T171: Sep26 is authoritative for the source record.
A172: SEP26-0169 | B172: base_row_0169 | C172: 169 | D172: Wind | E172: operational | F172: Tamil Nadu-Tirunelveli | G172: Tamil Nadu | H172: Tirunelveli | I172: Tirunelveli | K172: 3797.725 | L172: 1 | M172: =K172*L172 | N172: 3797.725 | P172: Direct | Q172: District carried from Sep26 base workbook | R172: Existing | T172: Sep26 is authoritative for the source record.
...

Sheet Allocation QC
A1: Source Record ID | B1: Base Excel Row | C1: Source | D1: Name of Power Plant | E1: Base Capacity (MW) | F1: Formula Allocated (MW) | G1: Formula Difference (MW) | H1: Formula Check | I1: Verified Allocated (MW) | J1: Verified Difference (MW) | K1: Verified Check | L1: Allocation Rows
A2: SEP26-0002 | B2: 2 | C2: Coal | D2: Ennore SEZ Expansion SCTPP | E2: 660 | F2: =SUMIF('District Allocation'!$A$2:$A$447,A2,'District Allocation'!$M$2:$M$447) | G2: =F2-E2 | H2: =IF(ABS(G2)<=0.000001,"OK","FAIL") | I2: 660 | J2: 0 | K2: OK | L2: 1
A3: SEP26-0003 | B3: 3 | C3: Coal | D3: Ennore SEZ Expansion SCTPP | E3: 660 | F3: =SUMIF('District Allocation'!$A$2:$A$447,A3,'District Allocation'!$M$2:$M$447) | G3: =F3-E3 | H3: =IF(ABS(G3)<=0.000001,"OK","FAIL") | I3: 660 | J3: 0 | K3: OK | L3: 1
A4: SEP26-0004 | B4: 4 | C4: Coal | D4: Ennore TPS | E4: 60 | F4: =SUMIF('District Allocation'!$A$2:$A$447,A4,'District Allocation'!$M$2:$M$447) | G4: =F4-E4 | H4: =IF(ABS(G4)<=0.000001,"OK","FAIL") | I4: 60 | J4: 0 | K4: OK | L4: 1
A5: SEP26-0005 | B5: 5 | C5: Coal | D5: Ennore TPS | E5: 60 | F5: =SUMIF('District Allocation'!$A$2:$A$447,A5,'District Allocation'!$M$2:$M$447) | G5: =F5-E5 | H5: =IF(ABS(G5)<=0.000001,"OK","FAIL") | I5: 60 | J5: 0 | K5: OK | L5: 1
A6: SEP26-0006 | B6: 6 | C6: Coal | D6: Ennore TPS | E6: 110 | F6: =SUMIF('District Allocation'!$A$2:$A$447,A6,'District Allocation'!$M$2:$M$447) | G6: =F6-E6 | H6: =IF(ABS(G6)<=0.000001,"OK","FAIL") | I6: 110 | J6: 0 | K6: OK | L6: 1
A7: SEP26-0007 | B7: 7 | C7: Coal | D7: Ennore TPS | E7: 110 | F7: =SUMIF('District Allocation'!$A$2:$A$447,A7,'District Allocation'!$M$2:$M$447) | G7: =F7-E7 | H7: =IF(ABS(G7)<=0.000001,"OK","FAIL") | I7: 110 | J7: 0 | K7: OK | L7: 1
A8: SEP26-0008 | B8: 8 | C8: Coal | D8: Ennore TPS | E8: 110 | F8: =SUMIF('District Allocation'!$A$2:$A$447,A8,'District Allocation'!$M$2:$M$447) | G8: =F8-E8 | H8: =IF(ABS(G8)<=0.000001,"OK","FAIL") | I8: 110 | J8: 0 | K8: OK | L8: 1
A9: SEP26-0009 | B9: 9 | C9: Coal | D9: ITPCL or Cuddalore TPP | E9: 600 | F9: =SUMIF('District Allocation'!$A$2:$A$447,A9,'District Allocation'!$M$2:$M$447) | G9: =F9-E9 | H9: =IF(ABS(G9)<=0.000001,"OK","FAIL") | I9: 600 | J9: 0 | K9: OK | L9: 1
A10: SEP26-0010 | B10: 10 | C10: Coal | D10: ITPCL or Cuddalore TPP | E10: 600 | F10: =SUMIF('District Allocation'!$A$2:$A$447,A10,'District Allocation'!$M$2:$M$447) | G10: =F10-E10 | H10: =IF(ABS(G10)<=0.000001,"OK","FAIL") | I10: 600 | J10: 0 | K10: OK | L10: 1
A11: SEP26-0011 | B11: 11 | C11: Coal | D11: Mettur TPS | E11: 210 | F11: =SUMIF('District Allocation'!$A$2:$A$447,A11,'District Allocation'!$M$2:$M$447) | G11: =F11-E11 | H11: =IF(ABS(G11)<=0.000001,"OK","FAIL") | I11: 210 | J11: 0 | K11: OK | L11: 1
A12: SEP26-0012 | B12: 12 | C12: Coal | D12: Mettur TPS | E12: 210 | F12: =SUMIF('District Allocation'!$A$2:$A$447,A12,'District Allocation'!$M$2:$M$447) | G12: =F12-E12 | H12: =IF(ABS(G12)<=0.000001,"OK","FAIL") | I12: 210 | J12: 0 | K12: OK | L12: 1
A13: SEP26-0013 | B13: 13 | C13: Coal | D13: Mettur TPS | E13: 210 | F13: =SUMIF('District Allocation'!$A$2:$A$447,A13,'District Allocation'!$M$2:$M$447) | G13: =F13-E13 | H13: =IF(ABS(G13)<=0.000001,"OK","FAIL") | I13: 210 | J13: 0 | K13: OK | L13: 1
... A323: SEP26-0323 | B323: 323 | C323: Small-Hydro | D323: Vaigai Hydro Power Project | E323: 3 | F323: =SUMIF('District Allocation'!$A$2:$A$447,A323,'District Allocation'!$M$2:$M$447) | G323: =F323-E323 | H323: =IF(ABS(G323)<=0.000001,"OK","FAIL") | I323: 3 | J323: 0 | K323: OK | L323: 1

Sheet Methodology
A1: Tamil Nadu Sep26 District Allocation - Methodology and Sources
A2: Quality control | B2: Value
A3: Sep26 base rows | B3: 322
A4: District allocation rows | B4: 446
A5: Rows failing verified reconciliation | B5: 0
A6: Operational solar MW | B6: 14121.46
A7: Operational wind MW | B7: 12299.49
A8: Wind turbine points assigned | B8: 12807
A9: Solar plant points assigned | B9: 343
A11: Topic | B11: Method / interpretation
A12: Authority | B12: Sep26 PlantInfo is authoritative for every source record, capacity, status, date, district, and agency.
A13: Scope | B13: Only statewide or unresolved solar and wind rows are redistributed. Direct Sep26 district records are retained.
A14: Stable matching | B14: Semantic allocation IDs are used; Excel row numbers and names containing capacity values are not used as merge keys.
A15: Solar utility | B15: Validated utility allocation shares are retained. The updated 9,143.18 MW unspecified row is multiplied by those shares.
A16: Solar Tenkasi | B16: The old combined Tirunelveli utility-solar share is split between Tirunelveli and Tenkasi using supplied OSM plant capacity proxies rejoined to current boundaries.
A17: Rooftop and off-grid | B17: The previous PM Surya Ghar-derived shares are retained because those allocations are based on installation counts rather than plant coordinates.
A18: Wind | B18: OSM turbine proxy is scaled to Sep26 operational wind. Known Sep26 district MW is subtracted; positive gaps are normalized to the 256.375 MW unresolved record.
A19: Boundary system | B19: Tenkasi is separate. Chengalpattu->Kanchipuram; Kallakurichi->Viluppuram; Mayiladuthurai->Nagapattinam; Ranipet and Tirupathur->Vellore.
A20: Boundary source | B20: https://cdn.jsdelivr.net/gh/udit-001/india-maps-data@2884453/geojson/states/tamil-nadu.geojson
A21: Limitations | B21: OSM is community-maintained. Most wind turbines lack MW tags, so turbine count is the main wind proxy. Solar footprint area is also a proxy where explicit MW tags are absent.

Sheet District Summary
A1: Operational Capacity Aggregated by Allocated District and Technology (MW)
A2: Operational records only. Values are independently verified from the allocation table. Sep26 remains authoritative for all source capacities.
A3: District | B3: Coal | C3: Oil & Gas | D3: Nuclear | E3: Bio Power | F3: Hydro | G3: Small-Hydro | H3: Wind | I3: Solar Utility | J3: Solar Rooftop | K3: Solar Off-grid | L3: Solar Total | M3: Total
A4: Ariyalur | B4: 0 | C4: 0 | D4: 0 | E4: 0 | F4: 0 | G4: 0 | H4: 22 | I4: 5.561021 | J4: 4.016099 | K4: 0.093184397 | L4: 9.6703044 | M4: 31.670304
A5: Chennai | B5: 0 | C5: 120 | D5: 0 | E5: 0.25 | F5: 0 | G5: 0 | H5: 3.125 | I5: 18.073221 | J5: 183.45384 | K5: 4.2681021 | L5: 205.79516 | M5: 329.17016
A6: Coimbatore | B6: 0 | C6: 0 | D6: 0 | E6: 11.6 | F6: 854 | G6: 53.5 | H6: 2175.4 | I6: 124.46219 | J6: 209.09059 | K6: 5.3839133 | L6: 338.93669 | M6: 3433.4367
A7: Cuddalore | B7: 4840 | C7: 0 | D7: 0 | E7: 90.68 | F7: 0 | G7: 0 | H7: 0 | I7: 944.04902 | J7: 36.554299 | K7: 5.0104028 | L7: 985.61372 | M7: 5916.2937
A8: Dharmapuri | B8: 0 | C8: 0 | D8: 0 | E8: 15 | F8: 0 | G8: 0 | H8: 196 | I8: 127.40246 | J8: 12.847618 | K8: 0.98660486 | L8: 141.23669 | M8: 352.23669
A9: Dindigul | B9: 0 | C9: 0 | D9: 0 | E9: 7.5 | F9: 0 | G9: 0 | H9: 319.62983 | I9: 407.8599 | J9: 23.823655 | K9: 0.89702609 | L9: 432.58058 | M9: 759.71041
A10: Erode | B10: 0 | C10: 0 | D10: 0 | E10: 97 | F10: 90 | G10: 16 | H10: 129.33 | I10: 825.79533 | J10: 78.255443 | K10: 6.2680727 | L10: 910.31885 | M10: 1242.6488
A11: Kanchipuram | B11: 0 | C11: 0 | D11: 440 | E11: 63 | F11: 0 | G11: 0 | H11: 7.65 | I11: 530.9621 | J11: 182.55704 | K11: 7.127541 | L11: 720.64668 | M11: 1231.2967
A12: Kanyakumari | B12: 0 | C12: 0 | D12: 0 | E12: 0 | F12: 100 | G12: 17.3 | H12: 349.375 | I12: 1.2862305 | J12: 36.300856 | K12: 0.84227838 | L12: 38.429365 | M12: 505.10436
A13: Karur | B13: 0 | C13: 0 | D13: 0 | E13: 22 | F13: 0 | G13: 0 | H13: 699.595 | I13: 470.90518 | J13: 43.163316 | K13: 2.0113138 | L13: 516.07981 | M13: 1237.6748
A14: Krishnagiri | B14: 0 | C14: 0 | D14: 0 | E14: 0 | F14: 0 | G14: 0 | H14: 0 | I14: 2.8519716 | J14: 17.760515 | K14: 0.41209216 | L14: 21.024579 | M14: 21.024579
A15: Location TBC | B15: 0 | C15: 0 | D15: 0 | E15: 0 | F15: 0 | G15: 0.35 | H15: 0 | I15: 0 | J15: 0 | K15: 0 | L15: 0 | M15: 0.35
... A38: Virudhunagar | B38: 0 | C38: 0 | D38: 0 | E38: 14.95 | F38: 0 | G38: 0 | H38: 0 | I38: 1170.5649 | J38: 41.506188 | K38: 1.6492665 | L38: 1213.7203 | M38: 1228.6703

Sheet Report Comparison
A1: District-Aggregated Capacity vs Tamil Nadu Resource Adequacy Report
A2: Important: the workbook represents operational physical capacity in the ICED dataset, while Table 6 reports capacity contracted to Tamil Nadu as of 31 March 2025. The comparison is therefore diagnostic, not a like-for-like validation.
A4: Technology | B4: District aggregate (MW) | C4: RA report Table 6 (MW) | D4: Difference (MW) | E4: Difference (%) | F4: Alignment note
A5: Coal | B5: ='District Summary'!B36 | C5: 12808 | D5: =B5-C5 | E5: =IF(C5=0,"",D5/C5) | F5: Physical installed capacity versus contracted capacity.
A6: Gas | B6: ='District Summary'!C36 | C6: 408 | D6: =B6-C6 | E6: =IF(C6=0,"",D6/C6) | F6: Workbook source: Oil & Gas.
A7: Nuclear | B7: ='District Summary'!D36 | C7: 1448 | D7: =B7-C7 | E7: =IF(C7=0,"",D7/C7) | F7: Physical station capacity versus Tamil Nadu's contracted share.
A8: Biomass | B8: ='District Summary'!E36 | C8: 891 | D8: =B8-C8 | E8: =IF(C8=0,"",D8/C8) | F8: Workbook source: Bio Power, including residual statewide categories.
A9: Hydro | B9: ='District Summary'!F36 | C9: 1866 | D9: =B9-C9 | E9: =IF(C9=0,"",D9/C9) | F9: Excludes the 400 MW Kadamparai PSP from workbook Hydro.
A10: PSP | B10: ='District Summary'!G36 | C10: 400 | D10: =B10-C10 | E10: =IF(C10=0,"",D10/C10) | F10: Workbook PSP is the 400 MW Kadamparai station.
A11: Hydro DRE | B11: ='District Summary'!H36 | C11: 58 | D11: =B11-C11 | E11: =IF(C11=0,"",D11/C11) | F11: Workbook source: Small-Hydro.
A12: Wind | B12: ='District Summary'!I36 | C12: 9331 | D12: =B12-C12 | E12: =IF(C12=0,"",D12/C12) | F12: Operational wind capacity in the workbook.
A13: Solar | B13: ='District Summary'!J36 | C13: 9006 | D13: =B13-C13 | E13: =IF(C13=0,"",D13/C13) | F13: Excludes rooftop and off-grid solar from workbook Solar.
A14: Solar DRE Rooftop | B14: ='District Summary'!K36 | C14: 1003 | D14: =B14-C14 | E14: =IF(C14=0,"",D14/C14) | F14: Workbook statewide rooftop category.
A15: Solar Off-grid | B15: ='District Summary'!L36 | F15: No separate Solar Off-grid line is given in Table 6.
A16: Comparable total excl. off-grid | B16: =SUM(B5:B14) | C16: 37220 | D16: =B16-C16 | E16: =D16/C16 | F16: The report states 37,220 MW; its displayed rounded components sum to 37,219 MW.
A17: Workbook total incl. off-grid | B17: =SUM(B5:B15) | F17: Includes 75.91 MW Solar Off-grid not separately reported in Table 6.
A19: Source and interpretation
A20: Report: upload/Tamil_Nadu_Resource_Adequacy_Report_2035_36_1.pdf - Table 6, page 5: Fuel-wise Contracted Capacity as on March 2025.
A21: Workbook: operational rows in District Allocation; pipeline, retired, and temporarily closed rows excluded.
A22: A positive difference does not necessarily mean the workbook is wrong: physical installed capacity, contracted shares, and reference dates differ.

Sheet Prayas TN Records
A1: Raw location | B1: Standardized district | C1: Name of plant | D1: Technology | E1: Subtype | F1: Installed capacity (MW) | G1: Commissioning date | H1: Financial year | I1: Use in validation? | J1: Data-quality note | K1: Source CSV row
A2: Karur | B2: Karur | C2: M/s. Kovai Medical Centre& Hospitals Ltd | D2: Solar | F2: 4 | G2: 42382 | H2: 13/01/2016 | I2: Yes | K2: 539
A3: Virudhunagar | B3: Virudhunagar | C3: M/s. MM Forgings Ltd | D3: Solar | F3: 1.8 | G3: 41546 | H3: 29/09/2013 | I3: Yes | K3: 542
A4: Virudhunagar | B4: Virudhunagar | C4: M/s. AK Ahamed & Co Narthampatti | D4: Solar | F4: 1 | G4: 42309 | H4: 01/11/2015 | I4: Yes | K4: 543
A5: Bharuch | B5: Bharuch | C5: Green Infra | D5: Solar | F5: 250 | G5: 43380 | H5: 07/10/2018 | I5: No | J5: Excluded: district is outside Tamil Nadu; source state tag appears incorrect. | K5: 921
A6: Cuddalore | B6: Cuddalore | C6: M/s. M.R.K. Co.Op Sugar Mills , Senthiathpoe | D6: Bagasse | F6: 7.5 | G6: 33770 | H6: 15/06/1992 | I6: Yes | K6: 992
A7: Tiruvannamalai | B7: Tiruvannamalai | C7: M/s. Cheyyar Co.Op Sugar Mills | D7: Bagasse | F7: 7.5 | G7: 34046 | H7: 18/03/1993 | I7: Yes | K7: 993
A8: Cuddalore | B8: Cuddalore | C8: M/s. Terra Energy Ltd | D8: Bagasse | F8: 18.68 | G8: 35016 | H8: 13/11/1995 | I8: Yes | K8: 994
A9: Theni | B9: Theni | C9: M/s. Rajashree Sugars & Chemicals Ltd | D9: Bagasse | F9: 12 | G9: 35153 | H9: 29/03/1996 | I9: Yes | K9: 995
A10: Tiruchirapalli | B10: Tiruchirappalli | C10: M/s. Kothari Sugars & Chemicals Ltd | D10: Bagasse | F10: 12 | G10: 35423 | H10: 24/12/1996 | I10: Yes | J10: District spelling standardized from Tiruchirapalli. | K10: 996
A11: Tiruvannamalai | B11: Tiruvannamalai | C11: M/s. Dharani Sugars & Chemicals Ltd | D11: Bagasse | F11: 15 | G11: 35332 | H11: 24/09/1996 | I11: Yes | K11: 997
A12: Cuddalore | B12: Cuddalore | C12: M/s. EID Parry (India) Ltd | D12: Bagasse | F12: 24.5 | G12: 35567 | H12: 17/05/1997 | I12: Yes | K12: 998
A13: Thanjavur | B13: Thanjavur | C13: M/s. Terra Energy Ltd | D13: Bagasse | F13: 28.42 | G13: 35566 | H13: 16/05/1997 | I13: Yes | K13: 999
A14: Dharmapuri | B14: Dharmapuri | C14: M/s. Subramania Siva Co-Op Sugar Mills,Gopalapuram | D14: Bagasse | F14: 5 | G14: 35962 | H14: 16/06/1998 | I14: Yes | K14: 1000
A15: Cuddalore | B15: Cuddalore | C15: M/s. Ambika Sugars (M/s SREL)Pennadam | D15: Bagasse | F15: 40 | G15: 37701 | H15: 21/03/2003 | I15: Yes | K15: 1001
A16: Erode | B16: Erode | C16: M/s. Bannari Amman Sugars Ltd | D16: Bagasse | F16: 20 | G16: 37404 | H16: 28/05/2002 | I16: Yes | K16: 1002
A17: Thanjavur | B17: Thanjavur | C17: M/s. Auro Energy Ltd ,Kottur | D17: Bagasse | F17: 16 | G17: 37613 | H17: 23/12/2002 | I17: Yes | K17: 1003
A18: Erode | B18: Erode | C18: M/s. Shakti Sugars Ltd ,Sakit Nagar | D18: Bagasse | F18: 32 | G18: 37935 | H18: 10/11/2003 | I18: Yes | K18: 1004
A19: Pudukkottai | B19: Pudukkottai | C19: M/s. EID Parry (India) Ltd,Aranthangi,Pudukottai | D19: Bagasse | F19: 18 | G19: 38806 | H19: 30/03/2006 | I19: Yes | K19: 1005
A20: Villupuram | B20: Viluppuram | C20: M/s. Rajashree Sugars & Chemicals Ltd,Mundiambakkam,Villupuram | D20: Bagasse | F20: 22 | G20: 38504 | H20: 01/06/2005 | I20: Yes | J20: District spelling standardized from Villupuram. | K20: 1006
A21: Perambalur | B21: Perambalur | C21: M/s. Kothari Sugars & Chemicals Ltd.Sathamangalam, | D21: Bagasse | F21: 22 | G21: 39148 | H21: 07/03/2007 | I21: Yes | K21: 1007
A22: Erode | B22: Erode | C22: M/s. Sakti Sugars Ltd | D22: Bagasse | F22: 24 | G22: 39341 | H22: 16/09/2007 | I22: Yes | K22: 1008
A23: Kanchipuram | B23: Kanchipuram | C23: M/s.S.V Sugars Mills Ltd | D23: Bagasse | F23: 45 | G23: 39288 | H23: 25/07/2007 | I23: Yes | K23: 1009
A24: Karur | B24: Karur | C24: M/s. EID Parry (India) Ltd | D24: Bagasse | F24: 22 | G24: 39318 | H24: 24/08/2007 | I24: Yes | K24: 1010
A25: Sivaganga | B25: Sivaganga | C25: M/s. Sakti Sugars Ltd | D25: Bagasse | F25: 35 | G25: 39479 | H25: 01/02/2008 | I25: Yes | K25: 1011
A26: Villupuram | B26: Viluppuram | C26: M/s. Rajashree Sugars & Chemicals Ltd Semmedu ,Villupuram | D26: Bagasse | F26: 23 | G26: 39730 | H26: 09/10/2008 | I26: Yes | J26: District spelling standardized from Villupuram. | K26: 1012
A27: Perambalur | B27: Perambalur | C27: M/s. Dhanalakahmi Srinivasan Sugars Pvt Ltd | D27: Bagasse | F27: 25 | G27: 40234 | H27: 25/02/2010 | I27: Yes | K27: 1013
A28: Tiruchirapalli | B28: Tiruchirappalli | C28: M/s. EID Parry (India) Ltd, Pettavaithalai | D28: Bagasse | F28: 20 | G28: 40191 | H28: 13/01/2010 | I28: Yes | J28: District spelling standardized from Tiruchirapalli. | K28: 1014
A29: Tiruvannamalai | B29: Tiruvannamalai | C29: M/s. Bannari Amman Sugars and Chemicals Ltd, Kolundampattu Village | D29: Bagasse | F29: 28.8 | G29: 40205 | H29: 27/01/2010 | I29: Yes | K29: 1015
A30: Villupuram | B30: Viluppuram | C30: M/s. Dharani Sugars & Chemicals, Kalayanallur Village | D30: Bagasse | F30: 22 | G30: 40098 | H30: 12/10/2009 | I30: Yes | J30: District spelling standardized from Villupuram. | K30: 1016
A31: Tirunelveli | B31: Tirunelveli | C31: M/s. Empee Sugars & Chemicals Ltd | D31: Bagasse | F31: 50 | G31: 40296 | H31: 28/04/2010 | I31: Yes | K31: 1017
A32: Villupuram | B32: Viluppuram | C32: M/s. Mardras Sugars & Chemicals | D32: Bagasse | F32: 25 | G32: 40683 | H32: 20/05/2011 | I32: Yes | J32: District spelling standardized from Villupuram. | K32: 1018
A33: Erode | B33: Erode | C33: M/s.Ponni Sugars Limited | D33: Bagasse | F33: 19 | G33: 41169 | H33: 17/09/2012 | I33: Yes | K33: 1019
A34: Erode | B34: Erode | C34: M/s.Chengalrayan Co-Operative Sugar Mills | D34: Bagasse | F34: 18 | G34: 42417 | H34: 17/02/2016 | I34: Yes | K34: 1020
A35: Erode | B35: Erode | C35: M/s. Cheyyar Co-Operative Sugar Mills | D35: Bagasse | F35: 15 | G35: 42766 | H35: 31/01/2017 | I35: Yes | K35: 1021
A36: Vellore | B36: Vellore | C36: M/s. Vellore Co-Operative Sugar Mills | D36: Bagasse | F36: 15 | G36: 42754 | H36: 19/01/2017 | I36: Yes | K36: 1022
A37: Cuddalore | B37: Cuddalore | C37: M/s.Perambalur Sugar Mills | D37: Bagasse | F37: 18 | G37: 43514 | H37: 18/02/2019 | I37: Yes | K37: 1023
A38: Thanjavur | B38: Thanjavur | C38: M/s.Arignar Anna Sugars Mills, | D38: Bagasse | F38: 15 | G38: 43347 | H38: 04/09/2018 | I38: Yes | K38: 1024
A39: Sivaganga | B39: Sivaganga | C39: M/s.Sapphire Industrial Infrastrucres Pvt Ltd | D39: Solar | F39: 5 | G39: 40532 | H39: 20/12/2010 | I39: Yes | K39: 2478
A40: karur | B40: Karur | C40: M/s. Shankar Abodes | D40: Solar | F40: 2 | G40: 40390 | H40: 31/07/2010 | I40: Yes | J40: District spelling standardized from karur. | K40: 2479
...

Sheet Prayas Validation
A1: Prayas Historical Validation of ICED District Allocation
A2: Prayas file contains 9,980 Tamil Nadu-tagged records through 2019-10-10. Distribution shares are compared because ICED is newer. Bharuch and Kachchh records (450 MW) are excluded as state-tag errors.
A3: District | B3: ICED Wind MW | C3: Prayas Wind MW | D3: Prayas–ICED wind share | E3: ICED Solar MW | F3: Prayas Solar MW | G3: Prayas–ICED solar share | H3: ICED Biomass MW | I3: Prayas Bagasse MW | J3: Prayas–ICED bio share | K3: Assessment
A4: Ariyalur | B4: ='District Summary'!I4 | C4: =SUMIFS('Prayas TN Records'!$F$2:$F$9981,'Prayas TN Records'!$B$2:$B$9981,$A4,'Prayas TN Records'!$D$2:$D$9981,"Wind",'Prayas TN Records'!$I$2:$I$9981,"Yes") | D4: =IF(SUM($C$4:$C$35)=0,0,C4/SUM($C$4:$C$35))-IF(SUM($B$4:$B$35)=0,0,B4/SUM($B$4:$B$35)) | E4: ='District Summary'!J4 | F4: =SUMIFS('Prayas TN Records'!$F$2:$F$9981,'Prayas TN Records'!$B$2:$B$9981,$A4,'Prayas TN Records'!$D$2:$D$9981,"Solar",'Prayas TN Records'!$I$2:$I$9981,"Yes") | G4: =IF(SUM($F$4:$F$35)=0,0,F4/SUM($F$4:$F$35))-IF(SUM($E$4:$E$35)=0,0,E4/SUM($E$4:$E$35)) | H4: ='District Summary'!E4 | I4: =SUMIFS('Prayas TN Records'!$F$2:$F$9981,'Prayas TN Records'!$B$2:$B$9981,$A4,'Prayas TN Records'!$D$2:$D$9981,"Bagasse",'Prayas TN Records'!$I$2:$I$9981,"Yes") | J4: =IF(SUM($I$4:$I$35)=0,0,I4/SUM($I$4:$I$35))-IF(SUM($H$4:$H$35)=0,0,H4/SUM($H$4:$H$35)) | K4: =IF(MAX(ABS(D4),ABS(G4),ABS(J4))>=0.05,"Large distribution difference",IF(MAX(ABS(D4),ABS(G4),ABS(J4))>=0.02,"Moderate difference","Broadly aligned"))
A5: Chennai | B5: ='District Summary'!I5 | C5: =SUMIFS('Prayas TN Records'!$F$2:$F$9981,'Prayas TN Records'!$B$2:$B$9981,$A5,'Prayas TN Records'!$D$2:$D$9981,"Wind",'Prayas TN Records'!$I$2:$I$9981,"Yes") | D5: =IF(SUM($C$4:$C$35)=0,0,C5/SUM($C$4:$C$35))-IF(SUM($B$4:$B$35)=0,0,B5/SUM($B$4:$B$35)) | E5: ='District Summary'!J5 | F5: =SUMIFS('Prayas TN Records'!$F$2:$F$9981,'Prayas TN Records'!$B$2:$B$9981,$A5,'Prayas TN Records'!$D$2:$D$9981,"Solar",'Prayas TN Records'!$I$2:$I$9981,"Yes") | G5: =IF(SUM($F$4:$F$35)=0,0,F5/SUM($F$4:$F$35))-IF(SUM($E$4:$E$35)=0,0,E5/SUM($E$4:$E$35)) | H5: ='District Summary'!E5 | I5: =SUMIFS('Prayas TN Records'!$F$2:$F$9981,'Prayas TN Records'!$B$2:$B$9981,$A5,'Prayas TN Records'!$D$2:$D$9981,"Bagasse",'Prayas TN Records'!$I$2:$I$9981,"Yes") | J5: =IF(SUM($I$4:$I$35)=0,0,I5/SUM($I$4:$I$35))-IF(SUM($H$4:$H$35)=0,0,H5/SUM($H$4:$H$35)) | K5: =IF(MAX(ABS(D5),ABS(G5),ABS(J5))>=0.05,"Large distribution difference",IF(MAX(ABS(D5),ABS(G5),ABS(J5))>=0.02,"Moderate difference","Broadly aligned"))
A6: Coimbatore | B6: ='District Summary'!I6 | C6: =SUMIFS('Prayas TN Records'!$F$2:$F$9981,'Prayas TN Records'!$B$2:$B$9981,$A6,'Prayas TN Records'!$D$2:$D$9981,"Wind",'Prayas TN Records'!$I$2:$I$9981,"Yes") | D6: =IF(SUM($C$4:$C$35)=0,0,C6/SUM($C$4:$C$35))-IF(SUM($B$4:$B$35)=0,0,B6/SUM($B$4:$B$35)) | E6: ='District Summary'!J6 | F6: =SUMIFS('Prayas TN Records'!$F$2:$F$9981,'Prayas TN Records'!$B$2:$B$9981,$A6,'Prayas TN Records'!$D$2:$D$9981,"Solar",'Prayas TN Records'!$I$2:$I$9981,"Yes") | G6: =IF(SUM($F$4:$F$35)=0,0,F6/SUM($F$4:$F$35))-IF(SUM($E$4:$E$35)=0,0,E6/SUM($E$4:$E$35)) | H6: ='District Summary'!E6 | I6: =SUMIFS('Prayas TN Records'!$F$2:$F$9981,'Prayas TN Records'!$B$2:$B$9981,$A6,'Prayas TN Records'!$D$2:$D$9981,"Bagasse",'Prayas TN Records'!$I$2:$I$9981,"Yes") | J6: =IF(SUM($I$4:$I$35)=0,0,I6/SUM($I$4:$I$35))-IF(SUM($H$4:$H$35)=0,0,H6/SUM($H$4:$H$35)) | K6: =IF(MAX(ABS(D6),ABS(G6),ABS(J6))>=0.05,"Large distribution difference",IF(MAX(ABS(D6),ABS(G6),ABS(J6))>=0.02,"Moderate difference","Broadly aligned"))
A7: Cuddalore | B7: ='District Summary'!I7 | C7: =SUMIFS('Prayas TN Records'!$F$2:$F$9981,'Prayas TN Records'!$B$2:$B$9981,$A7,'Prayas TN Records'!$D$2:$D$9981,"Wind",'Prayas TN Records'!$I$2:$I$9981,"Yes") | D7: =IF(SUM($C$4:$C$35)=0,0,C7/SUM($C$4:$C$35))-IF(SUM($B$4:$B$35)=0,0,B7/SUM($B$4:$B$35)) | E7: ='District Summary'!J7 | F7: =SUMIFS('Prayas TN Records'!$F$2:$F$9981,'Prayas TN Records'!$B$2:$B$9981,$A7,'Prayas TN Records'!$D$2:$D$9981,"Solar",'Prayas TN Records'!$I$2:$I$9981,"Yes") | G7: =IF(SUM($F$4:$F$35)=0,0,F7/SUM($F$4:$F$35))-IF(SUM($E$4:$E$35)=0,0,E7/SUM($E$4:$E$35)) | H7: ='District Summary'!E7 | I7: =SUMIFS('Prayas TN Records'!$F$2:$F$9981,'Prayas TN Records'!$B$2:$B$9981,$A7,'Prayas TN Records'!$D$2:$D$9981,"Bagasse",'Prayas TN Records'!$I$2:$I$9981,"Yes") | J7: =IF(SUM($I$4:$I$35)=0,0,I7/SUM($I$4:$I$35))-IF(SUM($H$4:$H$35)=0,0,H7/SUM($H$4:$H$35)) | K7: =IF(MAX(ABS(D7),ABS(G7),ABS(J7))>=0.05,"Large distribution difference",IF(MAX(ABS(D7),ABS(G7),ABS(J7))>=0.02,"Moderate difference","Broadly aligned"))
A8: Dharmapuri | B8: ='District Summary'!I8 | C8: =SUMIFS('Prayas TN Records'!$F$2:$F$9981,'Prayas TN Records'!$B$2:$B$9981,$A8,'Prayas TN Records'!$D$2:$D$9981,"Wind",'Prayas TN Records'!$I$2:$I$9981,"Yes") | D8: =IF(SUM($C$4:$C$35)=0,0,C8/SUM($C$4:$C$35))-IF(SUM($B$4:$B$35)=0,0,B8/SUM($B$4:$B$35)) | E8: ='District Summary'!J8 | F8: =SUMIFS('Prayas TN Records'!$F$2:$F$9981,'Prayas TN Records'!$B$2:$B$9981,$A8,'Prayas TN Records'!$D$2:$D$9981,"Solar",'Prayas TN Records'!$I$2:$I$9981,"Yes") | G8: =IF(SUM($F$4:$F$35)=0,0,F8/SUM($F$4:$F$35))-IF(SUM($E$4:$E$35)=0,0,E8/SUM($E$4:$E$35)) | H8: ='District Summary'!E8 | I8: =SUMIFS('Prayas TN Records'!$F$2:$F$9981,'Prayas TN Records'!$B$2:$B$9981,$A8,'Prayas TN Records'!$D$2:$D$9981,"Bagasse",'Prayas TN Records'!$I$2:$I$9981,"Yes") | J8: =IF(SUM($I$4:$I$35)=0,0,I8/SUM($I$4:$I$35))-IF(SUM($H$4:$H$35)=0,0,H8/SUM($H$4:$H$35)) | K8: =IF(MAX(ABS(D8),ABS(G8),ABS(J8))>=0.05,"Large distribution difference",IF(MAX(ABS(D8),ABS(G8),ABS(J8))>=0.02,"Moderate difference","Broadly aligned"))
A9: Dindigul | B9: ='District Summary'!I9 | C9: =SUMIFS('Prayas TN Records'!$F$2:$F$9981,'Prayas TN Records'!$B$2:$B$9981,$A9,'Prayas TN Records'!$D$2:$D$9981,"Wind",'Prayas TN Records'!$I$2:$I$9981,"Yes") | D9: =IF(SUM($C$4:$C$35)=0,0,C9/SUM($C$4:$C$35))-IF(SUM($B$4:$B$35)=0,0,B9/SUM($B$4:$B$35)) | E9: ='District Summary'!J9 | F9: =SUMIFS('Prayas TN Records'!$F$2:$F$9981,'Prayas TN Records'!$B$2:$B$9981,$A9,'Prayas TN Records'!$D$2:$D$9981,"Solar",'Prayas TN Records'!$I$2:$I$9981,"Yes") | G9: =IF(SUM($F$4:$F$35)=0,0,F9/SUM($F$4:$F$35))-IF(SUM($E$4:$E$35)=0,0,E9/SUM($E$4:$E$35)) | H9: ='District Summary'!E9 | I9: =SUMIFS('Prayas TN Records'!$F$2:$F$9981,'Prayas TN Records'!$B$2:$B$9981,$A9,'Prayas TN Records'!$D$2:$D$9981,"Bagasse",'Prayas TN Records'!$I$2:$I$9981,"Yes") | J9: =IF(SUM($I$4:$I$35)=0,0,I9/SUM($I$4:$I$35))-IF(SUM($H$4:$H$35)=0,0,H9/SUM($H$4:$H$35)) | K9: =IF(MAX(ABS(D9),ABS(G9),ABS(J9))>=0.05,"Large distribution difference",IF(MAX(ABS(D9),ABS(G9),ABS(J9))>=0.02,"Moderate difference","Broadly aligned"))
A10: Erode | B10: ='District Summary'!I10 | C10: =SUMIFS('Prayas TN Records'!$F$2:$F$9981,'Prayas TN Records'!$B$2:$B$9981,$A10,'Prayas TN Records'!$D$2:$D$9981,"Wind",'Prayas TN Records'!$I$2:$I$9981,"Yes") | D10: =IF(SUM($C$4:$C$35)=0,0,C10/SUM($C$4:$C$35))-IF(SUM($B$4:$B$35)=0,0,B10/SUM($B$4:$B$35)) | E10: ='District Summary'!J10 | F10: =SUMIFS('Prayas TN Records'!$F$2:$F$9981,'Prayas TN Records'!$B$2:$B$9981,$A10,'Prayas TN Records'!$D$2:$D$9981,"Solar",'Prayas TN Records'!$I$2:$I$9981,"Yes") | G10: =IF(SUM($F$4:$F$35)=0,0,F10/SUM($F$4:$F$35))-IF(SUM($E$4:$E$35)=0,0,E10/SUM($E$4:$E$35)) | H10: ='District Summary'!E10 | I10: =SUMIFS('Prayas TN Records'!$F$2:$F$9981,'Prayas TN Records'!$B$2:$B$9981,$A10,'Prayas TN Records'!$D$2:$D$9981,"Bagasse",'Prayas TN Records'!$I$2:$I$9981,"Yes") | J10: =IF(SUM($I$4:$I$35)=0,0,I10/SUM($I$4:$I$35))-IF(SUM($H$4:$H$35)=0,0,H10/SUM($H$4:$H$35)) | K10: =IF(MAX(ABS(D10),ABS(G10),ABS(J10))>=0.05,"Large distribution difference",IF(MAX(ABS(D10),ABS(G10),ABS(J10))>=0.02,"Moderate difference","Broadly aligned"))
A11: Kanchipuram | B11: ='District Summary'!I11 | C11: =SUMIFS('Prayas TN Records'!$F$2:$F$9981,'Prayas TN Records'!$B$2:$B$9981,$A11,'Prayas TN Records'!$D$2:$D$9981,"Wind",'Prayas TN Records'!$I$2:$I$9981,"Yes") | D11: =IF(SUM($C$4:$C$35)=0,0,C11/SUM($C$4:$C$35))-IF(SUM($B$4:$B$35)=0,0,B11/SUM($B$4:$B$35)) | E11: ='District Summary'!J11 | F11: =SUMIFS('Prayas TN Records'!$F$2:$F$9981,'Prayas TN Records'!$B$2:$B$9981,$A11,'Prayas TN Records'!$D$2:$D$9981,"Solar",'Prayas TN Records'!$I$2:$I$9981,"Yes") | G11: =IF(SUM($F$4:$F$35)=0,0,F11/SUM($F$4:$F$35))-IF(SUM($E$4:$E$35)=0,0,E11/SUM($E$4:$E$35)) | H11: ='District Summary'!E11 | I11: =SUMIFS('Prayas TN Records'!$F$2:$F$9981,'Prayas TN Records'!$B$2:$B$9981,$A11,'Prayas TN Records'!$D$2:$D$9981,"Bagasse",'Prayas TN Records'!$I$2:$I$9981,"Yes") | J11: =IF(SUM($I$4:$I$35)=0,0,I11/SUM($I$4:$I$35))-IF(SUM($H$4:$H$35)=0,0,H11/SUM($H$4:$H$35)) | K11: =IF(MAX(ABS(D11),ABS(G11),ABS(J11))>=0.05,"Large distribution difference",IF(MAX(ABS(D11),ABS(G11),ABS(J11))>=0.02,"Moderate difference","Broadly aligned"))
A12: Kanyakumari | B12: ='District Summary'!I12 | C12: =SUMIFS('Prayas TN Records'!$F$2:$F$9981,'Prayas TN Records'!$B$2:$B$9981,$A12,'Prayas TN Records'!$D$2:$D$9981,"Wind",'Prayas TN Records'!$I$2:$I$9981,"Yes") | D12: =IF(SUM($C$4:$C$35)=0,0,C12/SUM($C$4:$C$35))-IF(SUM($B$4:$B$35)=0,0,B12/SUM($B$4:$B$35)) | E12: ='District Summary'!J12 | F12: =SUMIFS('Prayas TN Records'!$F$2:$F$9981,'Prayas TN Records'!$B$2:$B$9981,$A12,'Prayas TN Records'!$D$2:$D$9981,"Solar",'Prayas TN Records'!$I$2:$I$9981,"Yes") | G12: =IF(SUM($F$4:$F$35)=0,0,F12/SUM($F$4:$F$35))-IF(SUM($E$4:$E$35)=0,0,E12/SUM($E$4:$E$35)) | H12: ='District Summary'!E12 | I12: =SUMIFS('Prayas TN Records'!$F$2:$F$9981,'Prayas TN Records'!$B$2:$B$9981,$A12,'Prayas TN Records'!$D$2:$D$9981,"Bagasse",'Prayas TN Records'!$I$2:$I$9981,"Yes") | J12: =IF(SUM($I$4:$I$35)=0,0,I12/SUM($I$4:$I$35))-IF(SUM($H$4:$H$35)=0,0,H12/SUM($H$4:$H$35)) | K12: =IF(MAX(ABS(D12),ABS(G12),ABS(J12))>=0.05,"Large distribution difference",IF(MAX(ABS(D12),ABS(G12),ABS(J12))>=0.02,"Moderate difference","Broadly aligned"))
A13: Karur | B13: ='District Summary'!I13 | C13: =SUMIFS('Prayas TN Records'!$F$2:$F$9981,'Prayas TN Records'!$B$2:$B$9981,$A13,'Prayas TN Records'!$D$2:$D$9981,"Wind",'Prayas TN Records'!$I$2:$I$9981,"Yes") | D13: =IF(SUM($C$4:$C$35)=0,0,C13/SUM($C$4:$C$35))-IF(SUM($B$4:$B$35)=0,0,B13/SUM($B$4:$B$35)) | E13: ='District Summary'!J13 | F13: =SUMIFS('Prayas TN Records'!$F$2:$F$9981,'Prayas TN Records'!$B$2:$B$9981,$A13,'Prayas TN Records'!$D$2:$D$9981,"Solar",'Prayas TN Records'!$I$2:$I$9981,"Yes") | G13: =IF(SUM($F$4:$F$35)=0,0,F13/SUM($F$4:$F$35))-IF(SUM($E$4:$E$35)=0,0,E13/SUM($E$4:$E$35)) | H13: ='District Summary'!E13 | I13: =SUMIFS('Prayas TN Records'!$F$2:$F$9981,'Prayas TN Records'!$B$2:$B$9981,$A13,'Prayas TN Records'!$D$2:$D$9981,"Bagasse",'Prayas TN Records'!$I$2:$I$9981,"Yes") | J13: =IF(SUM($I$4:$I$35)=0,0,I13/SUM($I$4:$I$35))-IF(SUM($H$4:$H$35)=0,0,H13/SUM($H$4:$H$35)) | K13: =IF(MAX(ABS(D13),ABS(G13),ABS(J13))>=0.05,"Large distribution difference",IF(MAX(ABS(D13),ABS(G13),ABS(J13))>=0.02,"Moderate difference","Broadly aligned"))
A14: Krishnagiri | B14: ='District Summary'!I14 | C14: =SUMIFS('Prayas TN Records'!$F$2:$F$9981,'Prayas TN Records'!$B$2:$B$9981,$A14,'Prayas TN Records'!$D$2:$D$9981,"Wind",'Prayas TN Records'!$I$2:$I$9981,"Yes") | D14: =IF(SUM($C$4:$C$35)=0,0,C14/SUM($C$4:$C$35))-IF(SUM($B$4:$B$35)=0,0,B14/SUM($B$4:$B$35)) | E14: ='District Summary'!J14 | F14: =SUMIFS('Prayas TN Records'!$F$2:$F$9981,'Prayas TN Records'!$B$2:$B$9981,$A14,'Prayas TN Records'!$D$2:$D$9981,"Solar",'Prayas TN Records'!$I$2:$I$9981,"Yes") | G14: =IF(SUM($F$4:$F$35)=0,0,F14/SUM($F$4:$F$35))-IF(SUM($E$4:$E$35)=0,0,E14/SUM($E$4:$E$35)) | H14: ='District Summary'!E14 | I14: =SUMIFS('Prayas TN Records'!$F$2:$F$9981,'Prayas TN Records'!$B$2:$B$9981,$A14,'Prayas TN Records'!$D$2:$D$9981,"Bagasse",'Prayas TN Records'!$I$2:$I$9981,"Yes") | J14: =IF(SUM($I$4:$I$35)=0,0,I14/SUM($I$4:$I$35))-IF(SUM($H$4:$H$35)=0,0,H14/SUM($H$4:$H$35)) | K14: =IF(MAX(ABS(D14),ABS(G14),ABS(J14))>=0.05,"Large distribution difference",IF(MAX(ABS(D14),ABS(G14),ABS(J14))>=0.02,"Moderate difference","Broadly aligned"))
A15: Madurai | B15: ='District Summary'!I15 | C15: =SUMIFS('Prayas TN Records'!$F$2:$F$9981,'Prayas TN Records'!$B$2:$B$9981,$A15,'Prayas TN Records'!$D$2:$D$9981,"Wind",'Prayas TN Records'!$I$2:$I$9981,"Yes") | D15: =IF(SUM($C$4:$C$35)=0,0,C15/SUM($C$4:$C$35))-IF(SUM($B$4:$B$35)=0,0,B15/SUM($B$4:$B$35)) | E15: ='District Summary'!J15 | F15: =SUMIFS('Prayas TN Records'!$F$2:$F$9981,'Prayas TN Records'!$B$2:$B$9981,$A15,'Prayas TN Records'!$D$2:$D$9981,"Solar",'Prayas TN Records'!$I$2:$I$9981,"Yes") | G15: =IF(SUM($F$4:$F$35)=0,0,F15/SUM($F$4:$F$35))-IF(SUM($E$4:$E$35)=0,0,E15/SUM($E$4:$E$35)) | H15: ='District Summary'!E15 | I15: =SUMIFS('Prayas TN Records'!$F$2:$F$9981,'Prayas TN Records'!$B$2:$B$9981,$A15,'Prayas TN Records'!$D$2:$D$9981,"Bagasse",'Prayas TN Records'!$I$2:$I$9981,"Yes") | J15: =IF(SUM($I$4:$I$35)=0,0,I15/SUM($I$4:$I$35))-IF(SUM($H$4:$H$35)=0,0,H15/SUM($H$4:$H$35)) | K15: =IF(MAX(ABS(D15),ABS(G15),ABS(J15))>=0.05,"Large distribution difference",IF(MAX(ABS(D15),ABS(G15),ABS(J15))>=0.02,"Moderate difference","Broadly aligned"))
... A35: Virudhunagar | B35: ='District Summary'!I35 | C35: =SUMIFS('Prayas TN Records'!$F$2:$F$9981,'Prayas TN Records'!$B$2:$B$9981,$A35,'Prayas TN Records'!$D$2:$D$9981,"Wind",'Prayas TN Records'!$I$2:$I$9981,"Yes") | D35: =IF(SUM($C$4:$C$35)=0,0,C35/SUM($C$4:$C$35))-IF(SUM($B$4:$B$35)=0,0,B35/SUM($B$4:$B$35)) | E35: ='District Summary'!J35 | F35: =SUMIFS('Prayas TN Records'!$F$2:$F$9981,'Prayas TN Records'!$B$2:$B$9981,$A35,'Prayas TN Records'!$D$2:$D$9981,"Solar",'Prayas TN Records'!$I$2:$I$9981,"Yes") | G35: =IF(SUM($F$4:$F$35)=0,0,F35/SUM($F$4:$F$35))-IF(SUM($E$4:$E$35)=0,0,E35/SUM($E$4:$E$35)) | H35: ='District Summary'!E35 | I35: =SUMIFS('Prayas TN Records'!$F$2:$F$9981,'Prayas TN Records'!$B$2:$B$9981,$A35,'Prayas TN Records'!$D$2:$D$9981,"Bagasse",'Prayas TN Records'!$I$2:$I$9981,"Yes") | J35: =IF(SUM($I$4:$I$35)=0,0,I35/SUM($I$4:$I$35))-IF(SUM($H$4:$H$35)=0,0,H35/SUM($H$4:$H$35)) | K35: =IF(MAX(ABS(D35),ABS(G35),ABS(J35))>=0.05,"Large distribution difference",IF(MAX(ABS(D35),ABS(G35),ABS(J35))>=0.02,"Moderate difference","Broadly aligned"))
A36: Total | B36: =SUM(B4:B35) | C36: =SUM(C4:C35) | E36: =SUM(E4:E35) | F36: =SUM(F4:F35) | H36: =SUM(H4:H35) | I36: =SUM(I4:I35) | K36: Historical benchmark only

Sheet Prayas Plant Evidence
A1: Plant-level Corrections and Residual Decomposition
A2: Prayas is used as historical evidence. Direct ICED corrections require agreement with CEA; missing plants are deducted from the statewide residual so total capacity is unchanged.
A4: Action | B4: Plant | C4: Prayas raw district | D4: Applied district | E4: Prayas MW | F4: Applied MW | G4: Prayas commissioning date | H4: ICED original row | I4: Confidence | J4: Evidence note
A5: Correct district | B5: Kothari Sugars & Chemicals Ltd., Kattur/Lalgudi | C5: Tiruchirapalli | D5: Tiruchirappalli | E5: 12 | F5: 12 | G5: 35423 | H5: 243 | I5: High | J5: Prayas identifies Tiruchirappalli; CEA confirms Kattur/Lalgudi, Trichy. CEA capacity is 11 MW, so ICED's 12 MW is retained.
A6: Correct district | B6: Madras Sugars & Chemicals Ltd., Vengur | C6: Villupuram | D6: Viluppuram | E6: 25 | F6: 25 | G6: 40683 | H6: 246 | I6: High | J6: Prayas and CEA both identify the 25 MW Vengur unit in Viluppuram.
A7: Fill missing plant | B7: Chengalrayan Co-operative Sugar Mills | C7: Erode | D7: Viluppuram | E7: 18 | F7: 18 | G7: 42417 | H7: 251 | I7: Medium | J7: Prayas plant is matched to the ICED residual; raw Prayas district corrected using official Tamil Nadu location evidence.
A8: Fill missing plant | B8: Vellore Co-operative Sugar Mills | C8: Vellore | D8: Vellore | E8: 15 | F8: 15 | G8: 42754 | H8: 251 | I8: Medium | J8: Prayas and CEA plant records agree.
A9: Fill missing plant | B9: Arignar Anna Co-operative Sugar Mills | C9: Thanjavur | D9: Thanjavur | E9: 15 | F9: 15 | G9: 43347 | H9: 251 | I9: Medium | J9: Prayas and CEA plant records agree.
A10: Fill missing plant | B10: Perambalur Co-operative Sugar Mills | C10: Cuddalore | D10: Perambalur | E10: 18 | F10: 18 | G10: 43514 | H10: 251 | I10: Medium | J10: Prayas plant is matched to the ICED residual; raw Prayas district corrected using CEA/Tamil Nadu evidence.
A11: Fill missing plant | B11: Cheyyar Co-operative Sugar Mills (15 MW unit) | C11: Erode | D11: Tiruvannamalai | E11: 15 | F11: 15 | G11: 42766 | H11: 251 | I11: Medium | J11: Prayas plant is matched to the ICED residual; raw Prayas district corrected using CEA/Tamil Nadu evidence.
A12: Fill missing plant | B12: Dharmapuri District Co-operative Sugar Mills | C12: Not in Prayas extract | D12: Dharmapuri | F12: 12 | H12: 251 | I12: Medium | J12: Later CEA plant record supplements the older Prayas extract.
A13: Residual proxy | B13: Unidentified balance of statewide bio-power residual | C13: — | D13: Multiple districts | F13: 45.2 | H13: 251 | I13: Low | J13: Remaining 45.2 MW retains the earlier ICED district proxy shares.
A15: Source | B15: Reference
A16: Prayas portal and supplied CSV | B16: https://energy.prayaspune.org/renewable-energy-data-portal/plant-wise-re
A17: CEA plant-wise renewable report | B17: https://cea.nic.in/wp-content/uploads/resd/2023/09/August_Plantwise_Details_2022.pdf

Sheet Solar District Evidence
A1: Sep26 Solar Allocation - Updated District Evidence
A2: Validated shares are retained. Current plant-coordinate geography is used only to split the former combined Tirunelveli utility share between Tirunelveli and Tenkasi.
A3: District | B3: Current OSM Solar Proxy MW | C3: Allocated Utility MW | D3: Allocated Rooftop MW | E3: Allocated Off-grid MW | F3: Total Allocated Solar MW | G3: Boundary Source
A4: Ariyalur | B4: 9.5248503 | C4: 5.561021 | D4: 4.016099 | E4: 0.093184397 | F4: 9.6703044 | G4: https://cdn.jsdelivr.net/gh/udit-001/india-maps-data@2884453/geojson/states/tamil-nadu.geojson
A5: Chennai | B5: 1.3277726 | C5: 18.073221 | D5: 183.45384 | E5: 4.2681021 | F5: 205.79516 | G5: https://cdn.jsdelivr.net/gh/udit-001/india-maps-data@2884453/geojson/states/tamil-nadu.geojson
A6: Coimbatore | B6: 34.446289 | C6: 124.46219 | D6: 209.09059 | E6: 5.3839133 | F6: 338.93669 | G6: https://cdn.jsdelivr.net/gh/udit-001/india-maps-data@2884453/geojson/states/tamil-nadu.geojson
A7: Cuddalore | B7: 155.30639 | C7: 944.04902 | D7: 36.554299 | E7: 5.0104028 | F7: 985.61372 | G7: https://cdn.jsdelivr.net/gh/udit-001/india-maps-data@2884453/geojson/states/tamil-nadu.geojson
A8: Dharmapuri | B8: 5.154152 | C8: 127.40246 | D8: 12.847618 | E8: 0.98660486 | F8: 141.23669 | G8: https://cdn.jsdelivr.net/gh/udit-001/india-maps-data@2884453/geojson/states/tamil-nadu.geojson
A9: Dindigul | B9: 374.69222 | C9: 407.8599 | D9: 23.823655 | E9: 0.89702609 | F9: 432.58058 | G9: https://cdn.jsdelivr.net/gh/udit-001/india-maps-data@2884453/geojson/states/tamil-nadu.geojson
A10: Erode | B10: 27.94737 | C10: 825.79533 | D10: 78.255443 | E10: 6.2680727 | F10: 910.31885 | G10: https://cdn.jsdelivr.net/gh/udit-001/india-maps-data@2884453/geojson/states/tamil-nadu.geojson
A11: Kanchipuram | B11: 14.576624 | C11: 530.9621 | D11: 182.55704 | E11: 7.127541 | F11: 720.64668 | G11: https://cdn.jsdelivr.net/gh/udit-001/india-maps-data@2884453/geojson/states/tamil-nadu.geojson
A12: Kanyakumari | B12: 0.96278868 | C12: 1.2862305 | D12: 36.300856 | E12: 0.84227838 | F12: 38.429365 | G12: https://cdn.jsdelivr.net/gh/udit-001/india-maps-data@2884453/geojson/states/tamil-nadu.geojson
A13: Karur | B13: 291.45121 | C13: 470.90518 | D13: 43.163316 | E13: 2.0113138 | F13: 516.07981 | G13: https://cdn.jsdelivr.net/gh/udit-001/india-maps-data@2884453/geojson/states/tamil-nadu.geojson
A14: Krishnagiri | B14: 3.9546342 | C14: 2.8519716 | D14: 17.760515 | E14: 0.41209216 | F14: 21.024579 | G14: https://cdn.jsdelivr.net/gh/udit-001/india-maps-data@2884453/geojson/states/tamil-nadu.geojson
A15: Madurai | B15: 75.667382 | C15: 104.47711 | D15: 65.466312 | E15: 1.9779996 | F15: 171.92142 | G15: https://cdn.jsdelivr.net/gh/udit-001/india-maps-data@2884453/geojson/states/tamil-nadu.geojson
... A37: Virudhunagar | B37: 793.68001 | C37: 1170.5649 | D37: 41.506188 | E37: 1.6492665 | F37: 1213.7203 | G37: https://cdn.jsdelivr.net/gh/udit-001/india-maps-data@2884453/geojson/states/tamil-nadu.geojson

Sheet Solar Allocation QC
